2025-04-07 00:00:54,139 - INFO - _client - _client.py:1025 - HTTP Request: GET https://raw.githubusercontent.com/BerriAI/litellm/main/model_prices_and_context_window.json "HTTP/1.1 200 OK"
2025-04-07 00:00:55,654 - INFO - testing_goldens_mak - testing_goldens_mak.py:122 - Loaded total of 851 Chunks
2025-04-07 00:00:55,806 - INFO - testing_goldens_mak - testing_goldens_mak.py:222 - Testing Attack @ 2025-04-07 00:00:55.806824+08:00
2025-04-07 00:01:33,723 - INFO - _client - _client.py:1025 - HTTP Request: POST http://localhost:11434/api/chat "HTTP/1.1 200 OK"
2025-04-07 00:01:45,577 - INFO - _client - _client.py:1025 - HTTP Request: POST http://localhost:11434/api/chat "HTTP/1.1 200 OK"
2025-04-07 00:01:59,490 - ERROR - __init__ - __init__.py:154 - Failed to detach context
Traceback (most recent call last):
  File "G:\inventoryScanner\.venv\ragflow_capstone\Lib\site-packages\opentelemetry\trace\__init__.py", line 589, in use_span
    yield span
  File "G:\inventoryScanner\.venv\ragflow_capstone\Lib\site-packages\opentelemetry\sdk\trace\__init__.py", line 1105, in start_as_current_span
    yield span
  File "G:\inventoryScanner\.venv\ragflow_capstone\Lib\site-packages\deepeval\telemetry.py", line 237, in capture_red_teamer_run
    yield span
  File "G:\inventoryScanner\.venv\ragflow_capstone\Lib\site-packages\deepeval\red_teaming\red_teamer.py", line 303, in a_scan
    await self.attack_synthesizer.a_generate_attacks(
GeneratorExit

During handling of the above exception, another exception occurred:

Traceback (most recent call last):
  File "G:\inventoryScanner\.venv\ragflow_capstone\Lib\site-packages\opentelemetry\context\__init__.py", line 152, in detach
    _RUNTIME_CONTEXT.detach(token)
  File "G:\inventoryScanner\.venv\ragflow_capstone\Lib\site-packages\opentelemetry\context\contextvars_context.py", line 50, in detach
    self._current_context.reset(token)  # type: ignore
    ^^^^^^^^^^^^^^^^^^^^^^^^^^^^^^^^^^
ValueError: <Token var=<ContextVar name='current_context' default={} at 0x000001D5EF58A430> at 0x000001D5A531BC40> was created in a different Context
2025-04-07 00:01:59,534 - WARNING - __init__ - __init__.py:213 - Already shutdown, dropping span.
2025-04-07 00:01:59,534 - ERROR - base_events - base_events.py:1820 - Task exception was never retrieved
future: <Task finished name='Task-7' coro=<AttackSynthesizer.a_generate_attacks.<locals>.throttled_attack_enhancement() done, defined at G:\inventoryScanner\.venv\ragflow_capstone\Lib\site-packages\deepeval\red_teaming\attack_synthesizer.py:186> exception=KeyboardInterrupt()>
Traceback (most recent call last):
  File "C:\Users\Admin\Desktop\BT4240\ragflow\ragflow_capstone\main.py", line 41, in main
    loop.run_until_complete(run_test(generate_attacks=False, fetch_chunks=False,
  File "C:\Users\Admin\AppData\Local\Programs\Python\Python312\Lib\asyncio\base_events.py", line 674, in run_until_complete
    self.run_forever()
  File "C:\Users\Admin\AppData\Local\Programs\Python\Python312\Lib\asyncio\base_events.py", line 641, in run_forever
    self._run_once()
  File "C:\Users\Admin\AppData\Local\Programs\Python\Python312\Lib\asyncio\base_events.py", line 1986, in _run_once
    handle._run()
  File "C:\Users\Admin\AppData\Local\Programs\Python\Python312\Lib\asyncio\events.py", line 88, in _run
    self._context.run(self._callback, *self._args)
  File "C:\Users\Admin\Desktop\BT4240\ragflow\ragflow_capstone\ragflow_python\testing_bot\testing_goldens_mak.py", line 236, in run_test
    results = red_teamer.scan(
              ^^^^^^^^^^^^^^^^
  File "G:\inventoryScanner\.venv\ragflow_capstone\Lib\site-packages\deepeval\red_teaming\red_teamer.py", line 120, in scan
    return loop.run_until_complete(
           ^^^^^^^^^^^^^^^^^^^^^^^^
  File "G:\inventoryScanner\.venv\ragflow_capstone\Lib\site-packages\nest_asyncio.py", line 92, in run_until_complete
    self._run_once()
  File "G:\inventoryScanner\.venv\ragflow_capstone\Lib\site-packages\nest_asyncio.py", line 133, in _run_once
    handle._run()
  File "C:\Users\Admin\AppData\Local\Programs\Python\Python312\Lib\asyncio\events.py", line 88, in _run
    self._context.run(self._callback, *self._args)
  File "C:\Users\Admin\AppData\Local\Programs\Python\Python312\Lib\asyncio\tasks.py", line 303, in __step
    self.__step_run_and_handle_result(exc)
  File "C:\Users\Admin\AppData\Local\Programs\Python\Python312\Lib\asyncio\tasks.py", line 314, in __step_run_and_handle_result
    result = coro.send(None)
             ^^^^^^^^^^^^^^^
  File "G:\inventoryScanner\.venv\ragflow_capstone\Lib\site-packages\deepeval\red_teaming\attack_synthesizer.py", line 194, in throttled_attack_enhancement
    result = await self.a_enhance_attack(
             ^^^^^^^^^^^^^^^^^^^^^^^^^^^^
  File "G:\inventoryScanner\.venv\ragflow_capstone\Lib\site-packages\deepeval\red_teaming\attack_synthesizer.py", line 484, in a_enhance_attack
    enhanced_attack = await MathProblem(
                      ^^^^^^^^^^^^^^^^^^
  File "G:\inventoryScanner\.venv\ragflow_capstone\Lib\site-packages\deepeval\red_teaming\attack_enhancements\math_problem\math_problem.py", line 109, in a_enhance
    await self._a_generate_schema(
  File "G:\inventoryScanner\.venv\ragflow_capstone\Lib\site-packages\deepeval\red_teaming\attack_enhancements\math_problem\math_problem.py", line 141, in _a_generate_schema
    return await a_generate_schema(
           ^^^^^^^^^^^^^^^^^^^^^^^^
  File "G:\inventoryScanner\.venv\ragflow_capstone\Lib\site-packages\deepeval\red_teaming\utils.py", line 42, in a_generate_schema
    res = await model.a_generate(prompt, schema=schema)
          ^^^^^^^^^^^^^^^^^^^^^^^^^^^^^^^^^^^^^^^^^^^^^
  File "C:\Users\Admin\Desktop\BT4240\ragflow\ragflow_capstone\ragflow_python\src\CustomLLama.py", line 42, in a_generate
    return self.generate(prompt, schema)
           ^^^^^^^^^^^^^^^^^^^^^^^^^^^^^
  File "C:\Users\Admin\Desktop\BT4240\ragflow\ragflow_capstone\ragflow_python\src\CustomLLama.py", line 26, in generate
    response = self.client.chat(model=self.model_name,
               ^^^^^^^^^^^^^^^^^^^^^^^^^^^^^^^^^^^^^^^
  File "G:\inventoryScanner\.venv\ragflow_capstone\Lib\site-packages\ollama\_client.py", line 333, in chat
    return self._request(
           ^^^^^^^^^^^^^^
  File "G:\inventoryScanner\.venv\ragflow_capstone\Lib\site-packages\ollama\_client.py", line 178, in _request
    return cls(**self._request_raw(*args, **kwargs).json())
                 ^^^^^^^^^^^^^^^^^^^^^^^^^^^^^^^^^^
  File "G:\inventoryScanner\.venv\ragflow_capstone\Lib\site-packages\ollama\_client.py", line 118, in _request_raw
    r = self._client.request(*args, **kwargs)
        ^^^^^^^^^^^^^^^^^^^^^^^^^^^^^^^^^^^^^
  File "G:\inventoryScanner\.venv\ragflow_capstone\Lib\site-packages\httpx\_client.py", line 825, in request
    return self.send(request, auth=auth, follow_redirects=follow_redirects)
           ^^^^^^^^^^^^^^^^^^^^^^^^^^^^^^^^^^^^^^^^^^^^^^^^^^^^^^^^^^^^^^^^
  File "G:\inventoryScanner\.venv\ragflow_capstone\Lib\site-packages\httpx\_client.py", line 914, in send
    response = self._send_handling_auth(
               ^^^^^^^^^^^^^^^^^^^^^^^^^
  File "G:\inventoryScanner\.venv\ragflow_capstone\Lib\site-packages\httpx\_client.py", line 942, in _send_handling_auth
    response = self._send_handling_redirects(
               ^^^^^^^^^^^^^^^^^^^^^^^^^^^^^^
  File "G:\inventoryScanner\.venv\ragflow_capstone\Lib\site-packages\httpx\_client.py", line 979, in _send_handling_redirects
    response = self._send_single_request(request)
               ^^^^^^^^^^^^^^^^^^^^^^^^^^^^^^^^^^
  File "G:\inventoryScanner\.venv\ragflow_capstone\Lib\site-packages\httpx\_client.py", line 1014, in _send_single_request
    response = transport.handle_request(request)
               ^^^^^^^^^^^^^^^^^^^^^^^^^^^^^^^^^
  File "G:\inventoryScanner\.venv\ragflow_capstone\Lib\site-packages\httpx\_transports\default.py", line 250, in handle_request
    resp = self._pool.handle_request(req)
           ^^^^^^^^^^^^^^^^^^^^^^^^^^^^^^
  File "G:\inventoryScanner\.venv\ragflow_capstone\Lib\site-packages\httpcore\_sync\connection_pool.py", line 256, in handle_request
    raise exc from None
  File "G:\inventoryScanner\.venv\ragflow_capstone\Lib\site-packages\httpcore\_sync\connection_pool.py", line 236, in handle_request
    response = connection.handle_request(
               ^^^^^^^^^^^^^^^^^^^^^^^^^^
  File "G:\inventoryScanner\.venv\ragflow_capstone\Lib\site-packages\httpcore\_sync\connection.py", line 103, in handle_request
    return self._connection.handle_request(request)
           ^^^^^^^^^^^^^^^^^^^^^^^^^^^^^^^^^^^^^^^^
  File "G:\inventoryScanner\.venv\ragflow_capstone\Lib\site-packages\httpcore\_sync\http11.py", line 136, in handle_request
    raise exc
  File "G:\inventoryScanner\.venv\ragflow_capstone\Lib\site-packages\httpcore\_sync\http11.py", line 106, in handle_request
    ) = self._receive_response_headers(**kwargs)
        ^^^^^^^^^^^^^^^^^^^^^^^^^^^^^^^^^^^^^^^^
  File "G:\inventoryScanner\.venv\ragflow_capstone\Lib\site-packages\httpcore\_sync\http11.py", line 177, in _receive_response_headers
    event = self._receive_event(timeout=timeout)
            ^^^^^^^^^^^^^^^^^^^^^^^^^^^^^^^^^^^^
  File "G:\inventoryScanner\.venv\ragflow_capstone\Lib\site-packages\httpcore\_sync\http11.py", line 217, in _receive_event
    data = self._network_stream.read(
           ^^^^^^^^^^^^^^^^^^^^^^^^^^
  File "G:\inventoryScanner\.venv\ragflow_capstone\Lib\site-packages\httpcore\_backends\sync.py", line 128, in read
    return self._sock.recv(max_bytes)
           ^^^^^^^^^^^^^^^^^^^^^^^^^^
KeyboardInterrupt
2025-04-07 00:01:59,611 - ERROR - base_events - base_events.py:1820 - Task was destroyed but it is pending!
task: <Task pending name='Task-8' coro=<AttackSynthesizer.a_generate_attacks.<locals>.throttled_attack_enhancement() running at G:\inventoryScanner\.venv\ragflow_capstone\Lib\site-packages\deepeval\red_teaming\attack_synthesizer.py:186> cb=[gather.<locals>._done_callback() at C:\Users\Admin\AppData\Local\Programs\Python\Python312\Lib\asyncio\tasks.py:767]>
2025-04-07 00:01:59,612 - ERROR - base_events - base_events.py:1820 - Task was destroyed but it is pending!
task: <Task pending name='Task-9' coro=<AttackSynthesizer.a_generate_attacks.<locals>.throttled_attack_enhancement() running at G:\inventoryScanner\.venv\ragflow_capstone\Lib\site-packages\deepeval\red_teaming\attack_synthesizer.py:186> cb=[gather.<locals>._done_callback() at C:\Users\Admin\AppData\Local\Programs\Python\Python312\Lib\asyncio\tasks.py:767]>
2025-04-07 00:01:59,612 - ERROR - base_events - base_events.py:1820 - Task was destroyed but it is pending!
task: <Task pending name='Task-10' coro=<AttackSynthesizer.a_generate_attacks.<locals>.throttled_attack_enhancement() running at G:\inventoryScanner\.venv\ragflow_capstone\Lib\site-packages\deepeval\red_teaming\attack_synthesizer.py:186> cb=[gather.<locals>._done_callback() at C:\Users\Admin\AppData\Local\Programs\Python\Python312\Lib\asyncio\tasks.py:767]>
2025-04-07 00:01:59,612 - ERROR - base_events - base_events.py:1820 - Task was destroyed but it is pending!
task: <Task pending name='Task-11' coro=<AttackSynthesizer.a_generate_attacks.<locals>.throttled_attack_enhancement() running at G:\inventoryScanner\.venv\ragflow_capstone\Lib\site-packages\deepeval\red_teaming\attack_synthesizer.py:186> cb=[gather.<locals>._done_callback() at C:\Users\Admin\AppData\Local\Programs\Python\Python312\Lib\asyncio\tasks.py:767]>
2025-04-07 00:01:59,612 - ERROR - base_events - base_events.py:1820 - Task was destroyed but it is pending!
task: <Task pending name='Task-12' coro=<AttackSynthesizer.a_generate_attacks.<locals>.throttled_attack_enhancement() running at G:\inventoryScanner\.venv\ragflow_capstone\Lib\site-packages\deepeval\red_teaming\attack_synthesizer.py:186> cb=[gather.<locals>._done_callback() at C:\Users\Admin\AppData\Local\Programs\Python\Python312\Lib\asyncio\tasks.py:767]>
2025-04-07 00:01:59,612 - ERROR - base_events - base_events.py:1820 - Task was destroyed but it is pending!
task: <Task pending name='Task-13' coro=<AttackSynthesizer.a_generate_attacks.<locals>.throttled_attack_enhancement() running at G:\inventoryScanner\.venv\ragflow_capstone\Lib\site-packages\deepeval\red_teaming\attack_synthesizer.py:186> cb=[gather.<locals>._done_callback() at C:\Users\Admin\AppData\Local\Programs\Python\Python312\Lib\asyncio\tasks.py:767]>
2025-04-07 00:01:59,612 - ERROR - base_events - base_events.py:1820 - Task was destroyed but it is pending!
task: <Task pending name='Task-14' coro=<AttackSynthesizer.a_generate_attacks.<locals>.throttled_attack_enhancement() running at G:\inventoryScanner\.venv\ragflow_capstone\Lib\site-packages\deepeval\red_teaming\attack_synthesizer.py:186> cb=[gather.<locals>._done_callback() at C:\Users\Admin\AppData\Local\Programs\Python\Python312\Lib\asyncio\tasks.py:767]>
2025-04-07 00:01:59,612 - ERROR - base_events - base_events.py:1820 - Task was destroyed but it is pending!
task: <Task pending name='Task-15' coro=<AttackSynthesizer.a_generate_attacks.<locals>.throttled_attack_enhancement() running at G:\inventoryScanner\.venv\ragflow_capstone\Lib\site-packages\deepeval\red_teaming\attack_synthesizer.py:186> cb=[gather.<locals>._done_callback() at C:\Users\Admin\AppData\Local\Programs\Python\Python312\Lib\asyncio\tasks.py:767]>
2025-04-07 00:01:59,612 - ERROR - base_events - base_events.py:1820 - Task was destroyed but it is pending!
task: <Task pending name='Task-16' coro=<AttackSynthesizer.a_generate_attacks.<locals>.throttled_attack_enhancement() running at G:\inventoryScanner\.venv\ragflow_capstone\Lib\site-packages\deepeval\red_teaming\attack_synthesizer.py:186> cb=[gather.<locals>._done_callback() at C:\Users\Admin\AppData\Local\Programs\Python\Python312\Lib\asyncio\tasks.py:767]>
2025-04-07 00:01:59,612 - ERROR - base_events - base_events.py:1820 - Task was destroyed but it is pending!
task: <Task pending name='Task-17' coro=<AttackSynthesizer.a_generate_attacks.<locals>.throttled_attack_enhancement() running at G:\inventoryScanner\.venv\ragflow_capstone\Lib\site-packages\deepeval\red_teaming\attack_synthesizer.py:186> cb=[gather.<locals>._done_callback() at C:\Users\Admin\AppData\Local\Programs\Python\Python312\Lib\asyncio\tasks.py:767]>
2025-04-07 00:01:59,612 - ERROR - base_events - base_events.py:1820 - Task was destroyed but it is pending!
task: <Task pending name='Task-18' coro=<AttackSynthesizer.a_generate_attacks.<locals>.throttled_attack_enhancement() running at G:\inventoryScanner\.venv\ragflow_capstone\Lib\site-packages\deepeval\red_teaming\attack_synthesizer.py:186> cb=[gather.<locals>._done_callback() at C:\Users\Admin\AppData\Local\Programs\Python\Python312\Lib\asyncio\tasks.py:767]>
2025-04-07 00:01:59,612 - ERROR - base_events - base_events.py:1820 - Task was destroyed but it is pending!
task: <Task pending name='Task-19' coro=<AttackSynthesizer.a_generate_attacks.<locals>.throttled_attack_enhancement() running at G:\inventoryScanner\.venv\ragflow_capstone\Lib\site-packages\deepeval\red_teaming\attack_synthesizer.py:186> cb=[gather.<locals>._done_callback() at C:\Users\Admin\AppData\Local\Programs\Python\Python312\Lib\asyncio\tasks.py:767]>
2025-04-07 00:01:59,612 - ERROR - base_events - base_events.py:1820 - Task was destroyed but it is pending!
task: <Task pending name='Task-20' coro=<AttackSynthesizer.a_generate_attacks.<locals>.throttled_attack_enhancement() running at G:\inventoryScanner\.venv\ragflow_capstone\Lib\site-packages\deepeval\red_teaming\attack_synthesizer.py:186> cb=[gather.<locals>._done_callback() at C:\Users\Admin\AppData\Local\Programs\Python\Python312\Lib\asyncio\tasks.py:767]>
2025-04-07 00:01:59,612 - ERROR - base_events - base_events.py:1820 - Task was destroyed but it is pending!
task: <Task pending name='Task-21' coro=<AttackSynthesizer.a_generate_attacks.<locals>.throttled_attack_enhancement() running at G:\inventoryScanner\.venv\ragflow_capstone\Lib\site-packages\deepeval\red_teaming\attack_synthesizer.py:186> cb=[gather.<locals>._done_callback() at C:\Users\Admin\AppData\Local\Programs\Python\Python312\Lib\asyncio\tasks.py:767]>
