2025-03-27 14:45:22,888 - INFO - testing_goldens - testing_goldens.py:142 - Loaded total of 791 Chunks
2025-03-27 14:45:24,948 - INFO - testing_goldens - testing_goldens.py:242 - Testing Attack @ 2025-03-27 14:45:24.948983+08:00
2025-03-27 14:45:44,746 - INFO - _client - _client.py:1025 - HTTP Request: POST http://localhost:11434/api/chat "HTTP/1.1 200 OK"
2025-03-27 14:45:57,987 - INFO - _client - _client.py:1025 - HTTP Request: POST http://localhost:11434/api/chat "HTTP/1.1 200 OK"
2025-03-27 14:46:12,915 - INFO - _client - _client.py:1025 - HTTP Request: POST http://localhost:11434/api/chat "HTTP/1.1 200 OK"
2025-03-27 14:46:45,524 - ERROR - __init__ - __init__.py:154 - Failed to detach context
Traceback (most recent call last):
  File "C:\Users\yinki\AppData\Local\Programs\Python\Python311\Lib\site-packages\opentelemetry\trace\__init__.py", line 589, in use_span
    yield span
  File "C:\Users\yinki\AppData\Local\Programs\Python\Python311\Lib\site-packages\opentelemetry\sdk\trace\__init__.py", line 1105, in start_as_current_span
    yield span
  File "C:\Users\yinki\AppData\Local\Programs\Python\Python311\Lib\site-packages\deepeval\telemetry.py", line 237, in capture_red_teamer_run
    yield span
  File "C:\Users\yinki\AppData\Local\Programs\Python\Python311\Lib\site-packages\deepeval\red_teaming\red_teamer.py", line 303, in a_scan
    await self.attack_synthesizer.a_generate_attacks(
GeneratorExit

During handling of the above exception, another exception occurred:

Traceback (most recent call last):
  File "C:\Users\yinki\AppData\Local\Programs\Python\Python311\Lib\site-packages\opentelemetry\context\__init__.py", line 152, in detach
    _RUNTIME_CONTEXT.detach(token)
  File "C:\Users\yinki\AppData\Local\Programs\Python\Python311\Lib\site-packages\opentelemetry\context\contextvars_context.py", line 50, in detach
    self._current_context.reset(token)  # type: ignore
    ^^^^^^^^^^^^^^^^^^^^^^^^^^^^^^^^^^
ValueError: <Token var=<ContextVar name='current_context' default={} at 0x000001FB4E39EC50> at 0x000001FB754C7F80> was created in a different Context
2025-03-27 14:46:45,592 - WARNING - __init__ - __init__.py:213 - Already shutdown, dropping span.
2025-03-27 14:46:45,594 - ERROR - base_events - base_events.py:1785 - Task exception was never retrieved
future: <Task finished name='Task-6' coro=<AttackSynthesizer.a_generate_attacks.<locals>.throttled_attack_enhancement() done, defined at C:\Users\yinki\AppData\Local\Programs\Python\Python311\Lib\site-packages\deepeval\red_teaming\attack_synthesizer.py:184> exception=KeyboardInterrupt()>
Traceback (most recent call last):
  File "c:\Users\yinki\OneDrive\NUS\BT4103\RAG Model\ragflow_capstone\main.py", line 37, in main
    loop.run_until_complete(run_test(generate_attacks=False, fetch_chunks=False,
  File "C:\Users\yinki\AppData\Local\Programs\Python\Python311\Lib\asyncio\base_events.py", line 641, in run_until_complete
    self.run_forever()
  File "C:\Users\yinki\AppData\Local\Programs\Python\Python311\Lib\asyncio\base_events.py", line 608, in run_forever
    self._run_once()
  File "C:\Users\yinki\AppData\Local\Programs\Python\Python311\Lib\asyncio\base_events.py", line 1936, in _run_once
    handle._run()
  File "C:\Users\yinki\AppData\Local\Programs\Python\Python311\Lib\asyncio\events.py", line 84, in _run
    self._context.run(self._callback, *self._args)
  File "c:\Users\yinki\OneDrive\NUS\BT4103\RAG Model\ragflow_capstone\ragflow_python\testing_bot\testing_goldens.py", line 252, in run_test
    results = red_teamer.scan(
              ^^^^^^^^^^^^^^^^
  File "C:\Users\yinki\AppData\Local\Programs\Python\Python311\Lib\site-packages\deepeval\red_teaming\red_teamer.py", line 120, in scan
    return loop.run_until_complete(
           ^^^^^^^^^^^^^^^^^^^^^^^^
  File "C:\Users\yinki\AppData\Roaming\Python\Python311\site-packages\nest_asyncio.py", line 92, in run_until_complete
    self._run_once()
  File "C:\Users\yinki\AppData\Roaming\Python\Python311\site-packages\nest_asyncio.py", line 133, in _run_once
    handle._run()
  File "C:\Users\yinki\AppData\Local\Programs\Python\Python311\Lib\asyncio\events.py", line 84, in _run
    self._context.run(self._callback, *self._args)
  File "C:\Users\yinki\AppData\Local\Programs\Python\Python311\Lib\asyncio\tasks.py", line 277, in __step
    result = coro.send(None)
             ^^^^^^^^^^^^^^^
  File "C:\Users\yinki\AppData\Local\Programs\Python\Python311\Lib\site-packages\deepeval\red_teaming\attack_synthesizer.py", line 192, in throttled_attack_enhancement
    result = await self.a_enhance_attack(
             ^^^^^^^^^^^^^^^^^^^^^^^^^^^^
  File "C:\Users\yinki\AppData\Local\Programs\Python\Python311\Lib\site-packages\deepeval\red_teaming\attack_synthesizer.py", line 483, in a_enhance_attack
    enhanced_attack = await MathProblem(
                      ^^^^^^^^^^^^^^^^^^
  File "C:\Users\yinki\AppData\Local\Programs\Python\Python311\Lib\site-packages\deepeval\red_teaming\attack_enhancements\math_problem\math_problem.py", line 89, in a_enhance
    res: EnhancedAttack = await self._a_generate_schema(
                          ^^^^^^^^^^^^^^^^^^^^^^^^^^^^^^
  File "C:\Users\yinki\AppData\Local\Programs\Python\Python311\Lib\site-packages\deepeval\red_teaming\attack_enhancements\math_problem\math_problem.py", line 141, in _a_generate_schema
    return await a_generate_schema(
           ^^^^^^^^^^^^^^^^^^^^^^^^
  File "C:\Users\yinki\AppData\Local\Programs\Python\Python311\Lib\site-packages\deepeval\red_teaming\utils.py", line 42, in a_generate_schema
    res = await model.a_generate(prompt, schema=schema)
          ^^^^^^^^^^^^^^^^^^^^^^^^^^^^^^^^^^^^^^^^^^^^^
  File "c:\Users\yinki\OneDrive\NUS\BT4103\RAG Model\ragflow_capstone\ragflow_python\src\CustomGemma2_2b.py", line 41, in a_generate
    return self.generate(prompt, schema)
           ^^^^^^^^^^^^^^^^^^^^^^^^^^^^^
  File "c:\Users\yinki\OneDrive\NUS\BT4103\RAG Model\ragflow_capstone\ragflow_python\src\CustomGemma2_2b.py", line 24, in generate
    response = self.client.chat(model=self.model_name,
              ^^^^^^^^^^^^^^^^^^^^^^^^^^^^^^^^^^^^^^^
  File "C:\Users\yinki\AppData\Local\Programs\Python\Python311\Lib\site-packages\ollama\_client.py", line 333, in chat
    return self._request(
           ^^^^^^^^^^^^^^
  File "C:\Users\yinki\AppData\Local\Programs\Python\Python311\Lib\site-packages\ollama\_client.py", line 178, in _request
    return cls(**self._request_raw(*args, **kwargs).json())
                 ^^^^^^^^^^^^^^^^^^^^^^^^^^^^^^^^^^
  File "C:\Users\yinki\AppData\Local\Programs\Python\Python311\Lib\site-packages\ollama\_client.py", line 118, in _request_raw
    r = self._client.request(*args, **kwargs)
        ^^^^^^^^^^^^^^^^^^^^^^^^^^^^^^^^^^^^^
  File "C:\Users\yinki\AppData\Local\Programs\Python\Python311\Lib\site-packages\httpx\_client.py", line 825, in request
    return self.send(request, auth=auth, follow_redirects=follow_redirects)
           ^^^^^^^^^^^^^^^^^^^^^^^^^^^^^^^^^^^^^^^^^^^^^^^^^^^^^^^^^^^^^^^^
  File "C:\Users\yinki\AppData\Local\Programs\Python\Python311\Lib\site-packages\httpx\_client.py", line 914, in send
    response = self._send_handling_auth(
               ^^^^^^^^^^^^^^^^^^^^^^^^^
  File "C:\Users\yinki\AppData\Local\Programs\Python\Python311\Lib\site-packages\httpx\_client.py", line 942, in _send_handling_auth
    response = self._send_handling_redirects(
               ^^^^^^^^^^^^^^^^^^^^^^^^^^^^^^
  File "C:\Users\yinki\AppData\Local\Programs\Python\Python311\Lib\site-packages\httpx\_client.py", line 979, in _send_handling_redirects
    response = self._send_single_request(request)
               ^^^^^^^^^^^^^^^^^^^^^^^^^^^^^^^^^^
  File "C:\Users\yinki\AppData\Local\Programs\Python\Python311\Lib\site-packages\httpx\_client.py", line 1014, in _send_single_request
    response = transport.handle_request(request)
               ^^^^^^^^^^^^^^^^^^^^^^^^^^^^^^^^^
  File "C:\Users\yinki\AppData\Local\Programs\Python\Python311\Lib\site-packages\httpx\_transports\default.py", line 250, in handle_request
    resp = self._pool.handle_request(req)
           ^^^^^^^^^^^^^^^^^^^^^^^^^^^^^^
  File "C:\Users\yinki\AppData\Local\Programs\Python\Python311\Lib\site-packages\httpcore\_sync\connection_pool.py", line 216, in handle_request
    raise exc from None
  File "C:\Users\yinki\AppData\Local\Programs\Python\Python311\Lib\site-packages\httpcore\_sync\connection_pool.py", line 196, in handle_request
    response = connection.handle_request(
               ^^^^^^^^^^^^^^^^^^^^^^^^^^
  File "C:\Users\yinki\AppData\Local\Programs\Python\Python311\Lib\site-packages\httpcore\_sync\connection.py", line 101, in handle_request
    return self._connection.handle_request(request)
           ^^^^^^^^^^^^^^^^^^^^^^^^^^^^^^^^^^^^^^^^
  File "C:\Users\yinki\AppData\Local\Programs\Python\Python311\Lib\site-packages\httpcore\_sync\http11.py", line 143, in handle_request
    raise exc
  File "C:\Users\yinki\AppData\Local\Programs\Python\Python311\Lib\site-packages\httpcore\_sync\http11.py", line 113, in handle_request
    ) = self._receive_response_headers(**kwargs)
        ^^^^^^^^^^^^^^^^^^^^^^^^^^^^^^^^^^^^^^^^
  File "C:\Users\yinki\AppData\Local\Programs\Python\Python311\Lib\site-packages\httpcore\_sync\http11.py", line 186, in _receive_response_headers
    event = self._receive_event(timeout=timeout)
            ^^^^^^^^^^^^^^^^^^^^^^^^^^^^^^^^^^^^
  File "C:\Users\yinki\AppData\Local\Programs\Python\Python311\Lib\site-packages\httpcore\_sync\http11.py", line 224, in _receive_event
    data = self._network_stream.read(
           ^^^^^^^^^^^^^^^^^^^^^^^^^^
  File "C:\Users\yinki\AppData\Local\Programs\Python\Python311\Lib\site-packages\httpcore\_backends\sync.py", line 126, in read
    return self._sock.recv(max_bytes)
           ^^^^^^^^^^^^^^^^^^^^^^^^^^
KeyboardInterrupt
2025-03-27 14:46:45,897 - ERROR - base_events - base_events.py:1785 - Task was destroyed but it is pending!
task: <Task pending name='Task-7' coro=<AttackSynthesizer.a_generate_attacks.<locals>.throttled_attack_enhancement() running at C:\Users\yinki\AppData\Local\Programs\Python\Python311\Lib\site-packages\deepeval\red_teaming\attack_synthesizer.py:184> cb=[gather.<locals>._done_callback() at C:\Users\yinki\AppData\Local\Programs\Python\Python311\Lib\asyncio\tasks.py:764]>
2025-03-27 14:46:45,898 - ERROR - base_events - base_events.py:1785 - Task was destroyed but it is pending!
task: <Task pending name='Task-8' coro=<AttackSynthesizer.a_generate_attacks.<locals>.throttled_attack_enhancement() running at C:\Users\yinki\AppData\Local\Programs\Python\Python311\Lib\site-packages\deepeval\red_teaming\attack_synthesizer.py:184> cb=[gather.<locals>._done_callback() at C:\Users\yinki\AppData\Local\Programs\Python\Python311\Lib\asyncio\tasks.py:764]>
2025-03-27 14:46:45,899 - ERROR - base_events - base_events.py:1785 - Task was destroyed but it is pending!
task: <Task pending name='Task-9' coro=<AttackSynthesizer.a_generate_attacks.<locals>.throttled_attack_enhancement() running at C:\Users\yinki\AppData\Local\Programs\Python\Python311\Lib\site-packages\deepeval\red_teaming\attack_synthesizer.py:184> cb=[gather.<locals>._done_callback() at C:\Users\yinki\AppData\Local\Programs\Python\Python311\Lib\asyncio\tasks.py:764]>
2025-03-27 14:46:45,899 - ERROR - base_events - base_events.py:1785 - Task was destroyed but it is pending!
task: <Task pending name='Task-10' coro=<AttackSynthesizer.a_generate_attacks.<locals>.throttled_attack_enhancement() running at C:\Users\yinki\AppData\Local\Programs\Python\Python311\Lib\site-packages\deepeval\red_teaming\attack_synthesizer.py:184> cb=[gather.<locals>._done_callback() at C:\Users\yinki\AppData\Local\Programs\Python\Python311\Lib\asyncio\tasks.py:764]>
2025-03-27 14:46:45,900 - ERROR - base_events - base_events.py:1785 - Task was destroyed but it is pending!
task: <Task pending name='Task-11' coro=<AttackSynthesizer.a_generate_attacks.<locals>.throttled_attack_enhancement() running at C:\Users\yinki\AppData\Local\Programs\Python\Python311\Lib\site-packages\deepeval\red_teaming\attack_synthesizer.py:184> cb=[gather.<locals>._done_callback() at C:\Users\yinki\AppData\Local\Programs\Python\Python311\Lib\asyncio\tasks.py:764]>
2025-03-27 14:46:45,901 - ERROR - base_events - base_events.py:1785 - Task was destroyed but it is pending!
task: <Task pending name='Task-12' coro=<AttackSynthesizer.a_generate_attacks.<locals>.throttled_attack_enhancement() running at C:\Users\yinki\AppData\Local\Programs\Python\Python311\Lib\site-packages\deepeval\red_teaming\attack_synthesizer.py:184> cb=[gather.<locals>._done_callback() at C:\Users\yinki\AppData\Local\Programs\Python\Python311\Lib\asyncio\tasks.py:764]>
2025-03-27 14:46:45,902 - ERROR - base_events - base_events.py:1785 - Task was destroyed but it is pending!
task: <Task pending name='Task-13' coro=<AttackSynthesizer.a_generate_attacks.<locals>.throttled_attack_enhancement() running at C:\Users\yinki\AppData\Local\Programs\Python\Python311\Lib\site-packages\deepeval\red_teaming\attack_synthesizer.py:184> cb=[gather.<locals>._done_callback() at C:\Users\yinki\AppData\Local\Programs\Python\Python311\Lib\asyncio\tasks.py:764]>
2025-03-27 14:46:45,902 - ERROR - base_events - base_events.py:1785 - Task was destroyed but it is pending!
task: <Task pending name='Task-14' coro=<AttackSynthesizer.a_generate_attacks.<locals>.throttled_attack_enhancement() running at C:\Users\yinki\AppData\Local\Programs\Python\Python311\Lib\site-packages\deepeval\red_teaming\attack_synthesizer.py:184> cb=[gather.<locals>._done_callback() at C:\Users\yinki\AppData\Local\Programs\Python\Python311\Lib\asyncio\tasks.py:764]>
2025-03-27 14:46:45,903 - ERROR - base_events - base_events.py:1785 - Task was destroyed but it is pending!
task: <Task pending name='Task-15' coro=<AttackSynthesizer.a_generate_attacks.<locals>.throttled_attack_enhancement() running at C:\Users\yinki\AppData\Local\Programs\Python\Python311\Lib\site-packages\deepeval\red_teaming\attack_synthesizer.py:184> cb=[gather.<locals>._done_callback() at C:\Users\yinki\AppData\Local\Programs\Python\Python311\Lib\asyncio\tasks.py:764]>
2025-03-27 14:46:45,904 - ERROR - base_events - base_events.py:1785 - Task was destroyed but it is pending!
task: <Task pending name='Task-16' coro=<AttackSynthesizer.a_generate_attacks.<locals>.throttled_attack_enhancement() running at C:\Users\yinki\AppData\Local\Programs\Python\Python311\Lib\site-packages\deepeval\red_teaming\attack_synthesizer.py:184> cb=[gather.<locals>._done_callback() at C:\Users\yinki\AppData\Local\Programs\Python\Python311\Lib\asyncio\tasks.py:764]>
2025-03-27 14:46:45,904 - ERROR - base_events - base_events.py:1785 - Task was destroyed but it is pending!
task: <Task pending name='Task-17' coro=<AttackSynthesizer.a_generate_attacks.<locals>.throttled_attack_enhancement() running at C:\Users\yinki\AppData\Local\Programs\Python\Python311\Lib\site-packages\deepeval\red_teaming\attack_synthesizer.py:184> cb=[gather.<locals>._done_callback() at C:\Users\yinki\AppData\Local\Programs\Python\Python311\Lib\asyncio\tasks.py:764]>
2025-03-27 14:46:45,905 - ERROR - base_events - base_events.py:1785 - Task was destroyed but it is pending!
task: <Task pending name='Task-18' coro=<AttackSynthesizer.a_generate_attacks.<locals>.throttled_attack_enhancement() running at C:\Users\yinki\AppData\Local\Programs\Python\Python311\Lib\site-packages\deepeval\red_teaming\attack_synthesizer.py:184> cb=[gather.<locals>._done_callback() at C:\Users\yinki\AppData\Local\Programs\Python\Python311\Lib\asyncio\tasks.py:764]>
2025-03-27 14:46:45,906 - ERROR - base_events - base_events.py:1785 - Task was destroyed but it is pending!
task: <Task pending name='Task-19' coro=<AttackSynthesizer.a_generate_attacks.<locals>.throttled_attack_enhancement() running at C:\Users\yinki\AppData\Local\Programs\Python\Python311\Lib\site-packages\deepeval\red_teaming\attack_synthesizer.py:184> cb=[gather.<locals>._done_callback() at C:\Users\yinki\AppData\Local\Programs\Python\Python311\Lib\asyncio\tasks.py:764]>
2025-03-27 14:46:45,906 - ERROR - base_events - base_events.py:1785 - Task was destroyed but it is pending!
task: <Task pending name='Task-20' coro=<AttackSynthesizer.a_generate_attacks.<locals>.throttled_attack_enhancement() running at C:\Users\yinki\AppData\Local\Programs\Python\Python311\Lib\site-packages\deepeval\red_teaming\attack_synthesizer.py:184> cb=[gather.<locals>._done_callback() at C:\Users\yinki\AppData\Local\Programs\Python\Python311\Lib\asyncio\tasks.py:764]>
2025-03-27 14:46:45,907 - ERROR - base_events - base_events.py:1785 - Task was destroyed but it is pending!
task: <Task pending name='Task-21' coro=<AttackSynthesizer.a_generate_attacks.<locals>.throttled_attack_enhancement() running at C:\Users\yinki\AppData\Local\Programs\Python\Python311\Lib\site-packages\deepeval\red_teaming\attack_synthesizer.py:184> cb=[gather.<locals>._done_callback() at C:\Users\yinki\AppData\Local\Programs\Python\Python311\Lib\asyncio\tasks.py:764]>
